Workbook

Sheet PB_CACHE
A1: H4sIAAAAAAAEAM2QvU7DMBSF3QZEEDyEdyIrLQ2lQxYCAokORYlYqqo41hWx6tjBP0jpY/DC4EQpDCyM3MH32tL57vFBI4TQp6+ud3U+9sfTiltW3Si1w0XbgMFLXmqq2wg/gzZcyXQaTxMyIzGJI5w5YZ2GVIKzmooIr1wpOHuEtlA7kKl0Qhx3/Pwbu+2x2wFLctCcCr6npYCMsgp+v1wUqlnCO4j+dsuZ9Ta8NvDck8FVmKm6oRp0+EBNlfM9oACFH6O8NRZqkikhoNcZcg/Sb2CHfvfm/DbbHgAvk/V6UOVWc/ka4dowpQUvfzLov/+XAMr5nCYsuZosLmcQXy82m3A8xH0aDMNRN/xHq525sy/9GUvhJwIAAA==

Sheet Portfolio Metrics 
A1: Global xUS Opp Value
A2: ='xUS Opp Value'!A2 -> as of 4/13/2026
H4: Total Number fo Stocks
B5: Portfolio Metrics | C5: Gbl xUS Opp Value (tgt) | D5: Gbl xUS Opp Value (d) | E5: BM | H5: % EM
B6: Forward P/E | C6: {=SUMPRODUCT('xUS Opp Value'!G4:G2041, --('xUS Opp Value'!$L4:$L2041>0)) / SUMPRODUCT(IF('xUS Opp Value'!$L4:$L2041>0, 'xUS Opp Value'!G4:G2041/'xUS Opp Value'!$L4:$L2041, 0))} -> 13.418169 | D6: {=SUMPRODUCT('xUS Opp Value'!H4:H2041, --('xUS Opp Value'!$L4:$L2041>0)) / SUMPRODUCT(IF('xUS Opp Value'!$L4:$L2041>0, 'xUS Opp Value'!H4:H2041/'xUS Opp Value'!$L4:$L2041, 0))} -> 13.450315 | E6: {=SUMPRODUCT('xUS Opp Value'!I4:I2041, --('xUS Opp Value'!$L4:$L2041>0)) / SUMPRODUCT(IF('xUS Opp Value'!$L4:$L2041>0, 'xUS Opp Value'!I4:I2041/'xUS Opp Value'!$L4:$L2041, 0))} -> 12.726655 | H6: %DM
B7: P/FV | C7: {=SUMPRODUCT('xUS Opp Value'!G4:G2165, --('xUS Opp Value'!J4:J2165>0)) / SUMPRODUCT(IF('xUS Opp Value'!J4:J2165>0, 'xUS Opp Value'!G4:G2165/'xUS Opp Value'!J4:J2165, 0))} -> 0.79580336 | D7: {=SUMPRODUCT('xUS Opp Value'!H4:H2041, --('xUS Opp Value'!J4:J2041>0)) / SUMPRODUCT(IF('xUS Opp Value'!J4:J2041>0, 'xUS Opp Value'!H4:H2041/'xUS Opp Value'!J4:J2041, 0))} -> 0.80392045 | E7: {=SUMPRODUCT('xUS Opp Value'!I4:I2041, --('xUS Opp Value'!J4:J2041>0)) / SUMPRODUCT(IF('xUS Opp Value'!J4:J2041>0, 'xUS Opp Value'!I4:I2041/'xUS Opp Value'!J4:J2041, 0))} -> 0.89279149
B8: MER Upside | C8: =(1/C7)-1 -> 0.25659183 | D8: =(1/D7)-1 -> 0.24390417 | E8: =(1/E7)-1 -> 0.12008237
M12: Forward P/E | P12: MER Upside | S12: MER P/FV
B13: Country | C13: Gbl xUS Opp Value (tgt) | D13: Gbl xUS Opp Value (d) | E13: BM | F13: Algo | G13: vs. BM | H13: vs. Algo | I13: Exp Algp | J13: vs Exp Algo | L13: Country | M13: Gbl xUS Opp Value (tgt) | N13: Gbl xUS Opp Value (d) | O13: BM | P13: xUS Opp Value (tgt) | Q13: xUS Opp Value (d) | R13: BM | S13: xUS Opp Value (tgt) | T13: xUS Opp Value (d) | U13: BM
A14: JP EQ | B14: Japan | C14: =SUMIF('xUS Opp Value'!E:E,'Portfolio Metrics '!B14,'xUS Opp Value'!G:G)/100 -> 0.1475 | D14: =SUMIF('xUS Opp Value'!E:E,'Portfolio Metrics '!B14,'xUS Opp Value'!H:H)/100 -> 0.14568342 | E14: =SUMIF('xUS Opp Value'!E:E,'Portfolio Metrics '!B14,'xUS Opp Value'!I:I)/100 -> 0.1442 | F14: =INDEX(Algo!$D:$D,MATCH('Portfolio Metrics '!A14,Algo!A:A,0)) -> 0.0816 | G14: =C14-E14 -> 0.0033 | H14: =C14-F14 -> 0.0659 | I14: =INDEX(#REF!,MATCH('Portfolio Metrics '!A14,#REF!,0)) -> #REF! | J14: =C14-I14 -> #REF! | L14: Japan | M14: {=IFERROR(SUMPRODUCT('xUS Opp Value'!G$4:G$2041, --('xUS Opp Value'!$L$4:$L$2041>0), --( ('xUS Opp Value'!$E$4:$E$2041=$L14) + ('xUS Opp Value'!$E$4:$E$2041="") > 0 )) / SUMPRODUCT(IF( ('xUS Opp Value'!$L$4:$L$2041>0) * ( ('xUS Opp Value'!$E$4:$E$2041=$L14) + ('xUS Opp Value'!$E$4:$E$2041="") > 0 ), 'xUS Opp Value'!G$4:G$2041/'xUS Opp Value'!$L$4:$L$2041, 0)),"")} | N14: {=IFERROR(SUMPRODUCT('xUS Opp Value'!H$4:H$2041, --('xUS Opp Value'!$L$4:$L$2041>0), --( ('xUS Opp Value'!$E$4:$E$2041=$L14) + ('xUS Opp Value'!$E$4:$E$2041="") > 0 )) / SUMPRODUCT(IF( ('xUS Opp Value'!$L$4:$L$2041>0) * ( ('xUS Opp Value'!$E$4:$E$2041=$L14) + ('xUS Opp Value'!$E$4:$E$2041="") > 0 ), 'xUS Opp Value'!H$4:H$2041/'xUS Opp Value'!$L$4:$L$2041, 0)),"")} | O14: {=IFERROR(SUMPRODUCT('xUS Opp Value'!I$4:I$2041, --('xUS Opp Value'!$L$4:$L$2041>0), --( ('xUS Opp Value'!$E$4:$E$2041=$L14) + ('xUS Opp Value'!$E$4:$E$2041="") > 0 )) / SUMPRODUCT(IF( ('xUS Opp Value'!$L$4:$L$2041>0) * ( ('xUS Opp Value'!$E$4:$E$2041=$L14) + ('xUS Opp Value'!$E$4:$E$2041="") > 0 ), 'xUS Opp Value'!I$4:I$2041/'xUS Opp Value'!$L$4:$L$2041, 0)),"")} | P14: =IFERROR((1/S14)-1,"") | Q14: =IFERROR((1/T14)-1,"") | R14: =IFERROR((1/U14)-1,"") | S14: {=IFERROR(SUMPRODUCT('xUS Opp Value'!G$4:G$2041, --('xUS Opp Value'!$J$4:$J$2041>0), --( ('xUS Opp Value'!$E$4:$E$2041=$L14) + ('xUS Opp Value'!$E$4:$E$2041="") > 0 )) / SUMPRODUCT(IF( ('xUS Opp Value'!$J$4:$J$2041>0) * ( ('xUS Opp Value'!$E$4:$E$2041=$L14) + ('xUS Opp Value'!$E$4:$E$2041="") > 0 ), 'xUS Opp Value'!G$4:G$2041/'xUS Opp Value'!$J$4:$J$2041, 0)),"")} | T14: {=IFERROR(SUMPRODUCT('xUS Opp Value'!H$4:H$2041, --('xUS Opp Value'!$J$4:$J$2041>0), --( ('xUS Opp Value'!$E$4:$E$2041=$L14) + ('xUS Opp Value'!$E$4:$E$2041="") > 0 )) / SUMPRODUCT(IF( ('xUS Opp Value'!$J$4:$J$2041>0) * ( ('xUS Opp Value'!$E$4:$E$2041=$L14) + ('xUS Opp Value'!$E$4:$E$2041="") > 0 ), 'xUS Opp Value'!H$4:H$2041/'xUS Opp Value'!$J$4:$J$2041, 0)),"")} | U14: {=IFERROR(SUMPRODUCT('xUS Opp Value'!I$4:I$2041, --('xUS Opp Value'!$J$4:$J$2041>0), --( ('xUS Opp Value'!$E$4:$E$2041=$L14) + ('xUS Opp Value'!$E$4:$E$2041="") > 0 )) / SUMPRODUCT(IF( ('xUS Opp Value'!$J$4:$J$2041>0) * ( ('xUS Opp Value'!$E$4:$E$2041=$L14) + ('xUS Opp Value'!$E$4:$E$2041="") > 0 ), 'xUS Opp Value'!I$4:I$2041/'xUS Opp Value'!$J$4:$J$2041, 0)),"")}
A15: UK EQ | B15: United Kingdom | C15: =SUMIF('xUS Opp Value'!E:E,'Portfolio Metrics '!B15,'xUS Opp Value'!G:G)/100 -> 0.1275 | D15: =SUMIF('xUS Opp Value'!E:E,'Portfolio Metrics '!B15,'xUS Opp Value'!H:H)/100 -> 0.13161007 | E15: =SUMIF('xUS Opp Value'!E:E,'Portfolio Metrics '!B15,'xUS Opp Value'!I:I)/100 -> 0.0866 | F15: =INDEX(Algo!$D:$D,MATCH('Portfolio Metrics '!A15,Algo!A:A,0)) -> 0.0867 | G15: =C15-E15 -> 0.0409 | H15: =C15-F15 -> 0.0408 | I15: =INDEX(#REF!,MATCH('Portfolio Metrics '!A15,#REF!,0)) -> #REF! | J15: =C15-I15 -> #REF! | L15: United Kingdom | M15: {=IFERROR(SUMPRODUCT('xUS Opp Value'!G$4:G$2041, --('xUS Opp Value'!$L$4:$L$2041>0), --( ('xUS Opp Value'!$E$4:$E$2041=$L15) + ('xUS Opp Value'!$E$4:$E$2041="") > 0 )) / SUMPRODUCT(IF( ('xUS Opp Value'!$L$4:$L$2041>0) * ( ('xUS Opp Value'!$E$4:$E$2041=$L15) + ('xUS Opp Value'!$E$4:$E$2041="") > 0 ), 'xUS Opp Value'!G$4:G$2041/'xUS Opp Value'!$L$4:$L$2041, 0)),"")} | N15: {=IFERROR(SUMPRODUCT('xUS Opp Value'!H$4:H$2041, --('xUS Opp Value'!$L$4:$L$2041>0), --( ('xUS Opp Value'!$E$4:$E$2041=$L15) + ('xUS Opp Value'!$E$4:$E$2041="") > 0 )) / SUMPRODUCT(IF( ('xUS Opp Value'!$L$4:$L$2041>0) * ( ('xUS Opp Value'!$E$4:$E$2041=$L15) + ('xUS Opp Value'!$E$4:$E$2041="") > 0 ), 'xUS Opp Value'!H$4:H$2041/'xUS Opp Value'!$L$4:$L$2041, 0)),"")} | O15: {=IFERROR(SUMPRODUCT('xUS Opp Value'!I$4:I$2041, --('xUS Opp Value'!$L$4:$L$2041>0), --( ('xUS Opp Value'!$E$4:$E$2041=$L15) + ('xUS Opp Value'!$E$4:$E$2041="") > 0 )) / SUMPRODUCT(IF( ('xUS Opp Value'!$L$4:$L$2041>0) * ( ('xUS Opp Value'!$E$4:$E$2041=$L15) + ('xUS Opp Value'!$E$4:$E$2041="") > 0 ), 'xUS Opp Value'!I$4:I$2041/'xUS Opp Value'!$L$4:$L$2041, 0)),"")} | P15: =IFERROR((1/S15)-1,"") | Q15: =IFERROR((1/T15)-1,"") | R15: =IFERROR((1/U15)-1,"") | S15: {=IFERROR(SUMPRODUCT('xUS Opp Value'!G$4:G$2041, --('xUS Opp Value'!$J$4:$J$2041>0), --( ('xUS Opp Value'!$E$4:$E$2041=$L15) + ('xUS Opp Value'!$E$4:$E$2041="") > 0 )) / SUMPRODUCT(IF( ('xUS Opp Value'!$J$4:$J$2041>0) * ( ('xUS Opp Value'!$E$4:$E$2041=$L15) + ('xUS Opp Value'!$E$4:$E$2041="") > 0 ), 'xUS Opp Value'!G$4:G$2041/'xUS Opp Value'!$J$4:$J$2041, 0)),"")} | T15: {=IFERROR(SUMPRODUCT('xUS Opp Value'!H$4:H$2041, --('xUS Opp Value'!$J$4:$J$2041>0), --( ('xUS Opp Value'!$E$4:$E$2041=$L15) + ('xUS Opp Value'!$E$4:$E$2041="") > 0 )) / SUMPRODUCT(IF( ('xUS Opp Value'!$J$4:$J$2041>0) * ( ('xUS Opp Value'!$E$4:$E$2041=$L15) + ('xUS Opp Value'!$E$4:$E$2041="") > 0 ), 'xUS Opp Value'!H$4:H$2041/'xUS Opp Value'!$J$4:$J$2041, 0)),"")} | U15: {=IFERROR(SUMPRODUCT('xUS Opp Value'!I$4:I$2041, --('xUS Opp Value'!$J$4:$J$2041>0), --( ('xUS Opp Value'!$E$4:$E$2041=$L15) + ('xUS Opp Value'!$E$4:$E$2041="") > 0 )) / SUMPRODUCT(IF( ('xUS Opp Value'!$J$4:$J$2041>0) * ( ('xUS Opp Value'!$E$4:$E$2041=$L15) + ('xUS Opp Value'!$E$4:$E$2041="") > 0 ), 'xUS Opp Value'!I$4:I$2041/'xUS Opp Value'!$J$4:$J$2041, 0)),"")}
A16: CA EQ | B16: Canada | C16: =SUMIF('xUS Opp Value'!E:E,'Portfolio Metrics '!B16,'xUS Opp Value'!G:G)/100 -> 0.0275 | D16: =SUMIF('xUS Opp Value'!E:E,'Portfolio Metrics '!B16,'xUS Opp Value'!H:H)/100 -> 0.028217641 | E16: =SUMIF('xUS Opp Value'!E:E,'Portfolio Metrics '!B16,'xUS Opp Value'!I:I)/100 -> 0.0835 | F16: =INDEX(Algo!$D:$D,MATCH('Portfolio Metrics '!A16,Algo!A:A,0)) -> 0.0424 | G16: =C16-E16 -> -0.056 | H16: =C16-F16 -> -0.0149 | I16: =INDEX(#REF!,MATCH('Portfolio Metrics '!A16,#REF!,0)) -> #REF! | J16: =C16-I16 -> #REF! | L16: Canada | M16: {=IFERROR(SUMPRODUCT('xUS Opp Value'!G$4:G$2041, --('xUS Opp Value'!$L$4:$L$2041>0), --( ('xUS Opp Value'!$E$4:$E$2041=$L16) + ('xUS Opp Value'!$E$4:$E$2041="") > 0 )) / SUMPRODUCT(IF( ('xUS Opp Value'!$L$4:$L$2041>0) * ( ('xUS Opp Value'!$E$4:$E$2041=$L16) + ('xUS Opp Value'!$E$4:$E$2041="") > 0 ), 'xUS Opp Value'!G$4:G$2041/'xUS Opp Value'!$L$4:$L$2041, 0)),"")} | N16: {=IFERROR(SUMPRODUCT('xUS Opp Value'!H$4:H$2041, --('xUS Opp Value'!$L$4:$L$2041>0), --( ('xUS Opp Value'!$E$4:$E$2041=$L16) + ('xUS Opp Value'!$E$4:$E$2041="") > 0 )) / SUMPRODUCT(IF( ('xUS Opp Value'!$L$4:$L$2041>0) * ( ('xUS Opp Value'!$E$4:$E$2041=$L16) + ('xUS Opp Value'!$E$4:$E$2041="") > 0 ), 'xUS Opp Value'!H$4:H$2041/'xUS Opp Value'!$L$4:$L$2041, 0)),"")} | O16: {=IFERROR(SUMPRODUCT('xUS Opp Value'!I$4:I$2041, --('xUS Opp Value'!$L$4:$L$2041>0), --( ('xUS Opp Value'!$E$4:$E$2041=$L16) + ('xUS Opp Value'!$E$4:$E$2041="") > 0 )) / SUMPRODUCT(IF( ('xUS Opp Value'!$L$4:$L$2041>0) * ( ('xUS Opp Value'!$E$4:$E$2041=$L16) + ('xUS Opp Value'!$E$4:$E$2041="") > 0 ), 'xUS Opp Value'!I$4:I$2041/'xUS Opp Value'!$L$4:$L$2041, 0)),"")} | P16: =IFERROR((1/S16)-1,"") | Q16: =IFERROR((1/T16)-1,"") | R16: =IFERROR((1/U16)-1,"") | S16: {=IFERROR(SUMPRODUCT('xUS Opp Value'!G$4:G$2041, --('xUS Opp Value'!$J$4:$J$2041>0), --( ('xUS Opp Value'!$E$4:$E$2041=$L16) + ('xUS Opp Value'!$E$4:$E$2041="") > 0 )) / SUMPRODUCT(IF( ('xUS Opp Value'!$J$4:$J$2041>0) * ( ('xUS Opp Value'!$E$4:$E$2041=$L16) + ('xUS Opp Value'!$E$4:$E$2041="") > 0 ), 'xUS Opp Value'!G$4:G$2041/'xUS Opp Value'!$J$4:$J$2041, 0)),"")} | T16: {=IFERROR(SUMPRODUCT('xUS Opp Value'!H$4:H$2041, --('xUS Opp Value'!$J$4:$J$2041>0), --( ('xUS Opp Value'!$E$4:$E$2041=$L16) + ('xUS Opp Value'!$E$4:$E$2041="") > 0 )) / SUMPRODUCT(IF( ('xUS Opp Value'!$J$4:$J$2041>0) * ( ('xUS Opp Value'!$E$4:$E$2041=$L16) + ('xUS Opp Value'!$E$4:$E$2041="") > 0 ), 'xUS Opp Value'!H$4:H$2041/'xUS Opp Value'!$J$4:$J$2041, 0)),"")} | U16: {=IFERROR(SUMPRODUCT('xUS Opp Value'!I$4:I$2041, --('xUS Opp Value'!$J$4:$J$2041>0), --( ('xUS Opp Value'!$E$4:$E$2041=$L16) + ('xUS Opp Value'!$E$4:$E$2041="") > 0 )) / SUMPRODUCT(IF( ('xUS Opp Value'!$J$4:$J$2041>0) * ( ('xUS Opp Value'!$E$4:$E$2041=$L16) + ('xUS Opp Value'!$E$4:$E$2041="") > 0 ), 'xUS Opp Value'!I$4:I$2041/'xUS Opp Value'!$J$4:$J$2041, 0)),"")}
A17: CH EQ | B17: Switzerland | C17: =SUMIF('xUS Opp Value'!E:E,'Portfolio Metrics '!B17,'xUS Opp Value'!G:G)/100 -> 0.05 | D17: =SUMIF('xUS Opp Value'!E:E,'Portfolio Metrics '!B17,'xUS Opp Value'!H:H)/100 -> 0.049099167 | E17: =SUMIF('xUS Opp Value'!E:E,'Portfolio Metrics '!B17,'xUS Opp Value'!I:I)/100 -> 0.048 | F17: =INDEX(Algo!$D:$D,MATCH('Portfolio Metrics '!A17,Algo!A:A,0)) -> 0.05 | G17: =C17-E17 -> 0.002 | H17: =C17-F17 -> 0 | I17: =INDEX(#REF!,MATCH('Portfolio Metrics '!A17,#REF!,0)) -> #REF! | J17: =C17-I17 -> #REF! | L17: Switzerland | M17: {=IFERROR(SUMPRODUCT('xUS Opp Value'!G$4:G$2041, --('xUS Opp Value'!$L$4:$L$2041>0), --( ('xUS Opp Value'!$E$4:$E$2041=$L17) + ('xUS Opp Value'!$E$4:$E$2041="") > 0 )) / SUMPRODUCT(IF( ('xUS Opp Value'!$L$4:$L$2041>0) * ( ('xUS Opp Value'!$E$4:$E$2041=$L17) + ('xUS Opp Value'!$E$4:$E$2041="") > 0 ), 'xUS Opp Value'!G$4:G$2041/'xUS Opp Value'!$L$4:$L$2041, 0)),"")} | N17: {=IFERROR(SUMPRODUCT('xUS Opp Value'!H$4:H$2041, --('xUS Opp Value'!$L$4:$L$2041>0), --( ('xUS Opp Value'!$E$4:$E$2041=$L17) + ('xUS Opp Value'!$E$4:$E$2041="") > 0 )) / SUMPRODUCT(IF( ('xUS Opp Value'!$L$4:$L$2041>0) * ( ('xUS Opp Value'!$E$4:$E$2041=$L17) + ('xUS Opp Value'!$E$4:$E$2041="") > 0 ), 'xUS Opp Value'!H$4:H$2041/'xUS Opp Value'!$L$4:$L$2041, 0)),"")} | O17: {=IFERROR(SUMPRODUCT('xUS Opp Value'!I$4:I$2041, --('xUS Opp Value'!$L$4:$L$2041>0), --( ('xUS Opp Value'!$E$4:$E$2041=$L17) + ('xUS Opp Value'!$E$4:$E$2041="") > 0 )) / SUMPRODUCT(IF( ('xUS Opp Value'!$L$4:$L$2041>0) * ( ('xUS Opp Value'!$E$4:$E$2041=$L17) + ('xUS Opp Value'!$E$4:$E$2041="") > 0 ), 'xUS Opp Value'!I$4:I$2041/'xUS Opp Value'!$L$4:$L$2041, 0)),"")} | P17: =IFERROR((1/S17)-1,"") | Q17: =IFERROR((1/T17)-1,"") | R17: =IFERROR((1/U17)-1,"") | S17: {=IFERROR(SUMPRODUCT('xUS Opp Value'!G$4:G$2041, --('xUS Opp Value'!$J$4:$J$2041>0), --( ('xUS Opp Value'!$E$4:$E$2041=$L17) + ('xUS Opp Value'!$E$4:$E$2041="") > 0 )) / SUMPRODUCT(IF( ('xUS Opp Value'!$J$4:$J$2041>0) * ( ('xUS Opp Value'!$E$4:$E$2041=$L17) + ('xUS Opp Value'!$E$4:$E$2041="") > 0 ), 'xUS Opp Value'!G$4:G$2041/'xUS Opp Value'!$J$4:$J$2041, 0)),"")} | T17: {=IFERROR(SUMPRODUCT('xUS Opp Value'!H$4:H$2041, --('xUS Opp Value'!$J$4:$J$2041>0), --( ('xUS Opp Value'!$E$4:$E$2041=$L17) + ('xUS Opp Value'!$E$4:$E$2041="") > 0 )) / SUMPRODUCT(IF( ('xUS Opp Value'!$J$4:$J$2041>0) * ( ('xUS Opp Value'!$E$4:$E$2041=$L17) + ('xUS Opp Value'!$E$4:$E$2041="") > 0 ), 'xUS Opp Value'!H$4:H$2041/'xUS Opp Value'!$J$4:$J$2041, 0)),"")} | U17: {=IFERROR(SUMPRODUCT('xUS Opp Value'!I$4:I$2041, --('xUS Opp Value'!$J$4:$J$2041>0), --( ('xUS Opp Value'!$E$4:$E$2041=$L17) + ('xUS Opp Value'!$E$4:$E$2041="") > 0 )) / SUMPRODUCT(IF( ('xUS Opp Value'!$J$4:$J$2041>0) * ( ('xUS Opp Value'!$E$4:$E$2041=$L17) + ('xUS Opp Value'!$E$4:$E$2041="") > 0 ), 'xUS Opp Value'!I$4:I$2041/'xUS Opp Value'!$J$4:$J$2041, 0)),"")}
A18: FR EQ | B18: France | C18: =SUMIF('xUS Opp Value'!E:E,'Portfolio Metrics '!B18,'xUS Opp Value'!G:G)/100 -> 0.0875 | D18: =SUMIF('xUS Opp Value'!E:E,'Portfolio Metrics '!B18,'xUS Opp Value'!H:H)/100 -> 0.086059471 | E18: =SUMIF('xUS Opp Value'!E:E,'Portfolio Metrics '!B18,'xUS Opp Value'!I:I)/100 -> 0.0539 | F18: =INDEX(Algo!$D:$D,MATCH('Portfolio Metrics '!A18,Algo!A:A,0)) -> 0.0546 | G18: =C18-E18 -> 0.0336 | H18: =C18-F18 -> 0.0329 | I18: =INDEX(#REF!,MATCH('Portfolio Metrics '!A18,#REF!,0)) -> #REF! | J18: =C18-I18 -> #REF! | L18: France | M18: {=IFERROR(SUMPRODUCT('xUS Opp Value'!G$4:G$2041, --('xUS Opp Value'!$L$4:$L$2041>0), --( ('xUS Opp Value'!$E$4:$E$2041=$L18) + ('xUS Opp Value'!$E$4:$E$2041="") > 0 )) / SUMPRODUCT(IF( ('xUS Opp Value'!$L$4:$L$2041>0) * ( ('xUS Opp Value'!$E$4:$E$2041=$L18) + ('xUS Opp Value'!$E$4:$E$2041="") > 0 ), 'xUS Opp Value'!G$4:G$2041/'xUS Opp Value'!$L$4:$L$2041, 0)),"")} | N18: {=IFERROR(SUMPRODUCT('xUS Opp Value'!H$4:H$2041, --('xUS Opp Value'!$L$4:$L$2041>0), --( ('xUS Opp Value'!$E$4:$E$2041=$L18) + ('xUS Opp Value'!$E$4:$E$2041="") > 0 )) / SUMPRODUCT(IF( ('xUS Opp Value'!$L$4:$L$2041>0) * ( ('xUS Opp Value'!$E$4:$E$2041=$L18) + ('xUS Opp Value'!$E$4:$E$2041="") > 0 ), 'xUS Opp Value'!H$4:H$2041/'xUS Opp Value'!$L$4:$L$2041, 0)),"")} | O18: {=IFERROR(SUMPRODUCT('xUS Opp Value'!I$4:I$2041, --('xUS Opp Value'!$L$4:$L$2041>0), --( ('xUS Opp Value'!$E$4:$E$2041=$L18) + ('xUS Opp Value'!$E$4:$E$2041="") > 0 )) / SUMPRODUCT(IF( ('xUS Opp Value'!$L$4:$L$2041>0) * ( ('xUS Opp Value'!$E$4:$E$2041=$L18) + ('xUS Opp Value'!$E$4:$E$2041="") > 0 ), 'xUS Opp Value'!I$4:I$2041/'xUS Opp Value'!$L$4:$L$2041, 0)),"")} | P18: =IFERROR((1/S18)-1,"") | Q18: =IFERROR((1/T18)-1,"") | R18: =IFERROR((1/U18)-1,"") | S18: {=IFERROR(SUMPRODUCT('xUS Opp Value'!G$4:G$2041, --('xUS Opp Value'!$J$4:$J$2041>0), --( ('xUS Opp Value'!$E$4:$E$2041=$L18) + ('xUS Opp Value'!$E$4:$E$2041="") > 0 )) / SUMPRODUCT(IF( ('xUS Opp Value'!$J$4:$J$2041>0) * ( ('xUS Opp Value'!$E$4:$E$2041=$L18) + ('xUS Opp Value'!$E$4:$E$2041="") > 0 ), 'xUS Opp Value'!G$4:G$2041/'xUS Opp Value'!$J$4:$J$2041, 0)),"")} | T18: {=IFERROR(SUMPRODUCT('xUS Opp Value'!H$4:H$2041, --('xUS Opp Value'!$J$4:$J$2041>0), --( ('xUS Opp Value'!$E$4:$E$2041=$L18) + ('xUS Opp Value'!$E$4:$E$2041="") > 0 )) / SUMPRODUCT(IF( ('xUS Opp Value'!$J$4:$J$2041>0) * ( ('xUS Opp Value'!$E$4:$E$2041=$L18) + ('xUS Opp Value'!$E$4:$E$2041="") > 0 ), 'xUS Opp Value'!H$4:H$2041/'xUS Opp Value'!$J$4:$J$2041, 0)),"")} | U18: {=IFERROR(SUMPRODUCT('xUS Opp Value'!I$4:I$2041, --('xUS Opp Value'!$J$4:$J$2041>0), --( ('xUS Opp Value'!$E$4:$E$2041=$L18) + ('xUS Opp Value'!$E$4:$E$2041="") > 0 )) / SUMPRODUCT(IF( ('xUS Opp Value'!$J$4:$J$2041>0) * ( ('xUS Opp Value'!$E$4:$E$2041=$L18) + ('xUS Opp Value'!$E$4:$E$2041="") > 0 ), 'xUS Opp Value'!I$4:I$2041/'xUS Opp Value'!$J$4:$J$2041, 0)),"")}
A19: AU EQ | B19: Australia | C19: =SUMIF('xUS Opp Value'!E:E,'Portfolio Metrics '!B19,'xUS Opp Value'!G:G)/100 -> 0.03 | D19: =SUMIF('xUS Opp Value'!E:E,'Portfolio Metrics '!B19,'xUS Opp Value'!H:H)/100 -> 0.032184788 | E19: =SUMIF('xUS Opp Value'!E:E,'Portfolio Metrics '!B19,'xUS Opp Value'!I:I)/100 -> 0.0404 | F19: =INDEX(Algo!$D:$D,MATCH('Portfolio Metrics '!A19,Algo!A:A,0)) -> 0.0399 | G19: =C19-E19 -> -0.0104 | H19: =C19-F19 -> -0.0099 | I19: =INDEX(#REF!,MATCH('Portfolio Metrics '!A19,#REF!,0)) -> #REF! | J19: =C19-I19 -> #REF! | L19: Australia | M19: {=IFERROR(SUMPRODUCT('xUS Opp Value'!G$4:G$2041, --('xUS Opp Value'!$L$4:$L$2041>0), --( ('xUS Opp Value'!$E$4:$E$2041=$L19) + ('xUS Opp Value'!$E$4:$E$2041="") > 0 )) / SUMPRODUCT(IF( ('xUS Opp Value'!$L$4:$L$2041>0) * ( ('xUS Opp Value'!$E$4:$E$2041=$L19) + ('xUS Opp Value'!$E$4:$E$2041="") > 0 ), 'xUS Opp Value'!G$4:G$2041/'xUS Opp Value'!$L$4:$L$2041, 0)),"")} | N19: {=IFERROR(SUMPRODUCT('xUS Opp Value'!H$4:H$2041, --('xUS Opp Value'!$L$4:$L$2041>0), --( ('xUS Opp Value'!$E$4:$E$2041=$L19) + ('xUS Opp Value'!$E$4:$E$2041="") > 0 )) / SUMPRODUCT(IF( ('xUS Opp Value'!$L$4:$L$2041>0) * ( ('xUS Opp Value'!$E$4:$E$2041=$L19) + ('xUS Opp Value'!$E$4:$E$2041="") > 0 ), 'xUS Opp Value'!H$4:H$2041/'xUS Opp Value'!$L$4:$L$2041, 0)),"")} | O19: {=IFERROR(SUMPRODUCT('xUS Opp Value'!I$4:I$2041, --('xUS Opp Value'!$L$4:$L$2041>0), --( ('xUS Opp Value'!$E$4:$E$2041=$L19) + ('xUS Opp Value'!$E$4:$E$2041="") > 0 )) / SUMPRODUCT(IF( ('xUS Opp Value'!$L$4:$L$2041>0) * ( ('xUS Opp Value'!$E$4:$E$2041=$L19) + ('xUS Opp Value'!$E$4:$E$2041="") > 0 ), 'xUS Opp Value'!I$4:I$2041/'xUS Opp Value'!$L$4:$L$2041, 0)),"")} | P19: =IFERROR((1/S19)-1,"") | Q19: =IFERROR((1/T19)-1,"") | R19: =IFERROR((1/U19)-1,"") | S19: {=IFERROR(SUMPRODUCT('xUS Opp Value'!G$4:G$2041, --('xUS Opp Value'!$J$4:$J$2041>0), --( ('xUS Opp Value'!$E$4:$E$2041=$L19) + ('xUS Opp Value'!$E$4:$E$2041="") > 0 )) / SUMPRODUCT(IF( ('xUS Opp Value'!$J$4:$J$2041>0) * ( ('xUS Opp Value'!$E$4:$E$2041=$L19) + ('xUS Opp Value'!$E$4:$E$2041="") > 0 ), 'xUS Opp Value'!G$4:G$2041/'xUS Opp Value'!$J$4:$J$2041, 0)),"")} | T19: {=IFERROR(SUMPRODUCT('xUS Opp Value'!H$4:H$2041, --('xUS Opp Value'!$J$4:$J$2041>0), --( ('xUS Opp Value'!$E$4:$E$2041=$L19) + ('xUS Opp Value'!$E$4:$E$2041="") > 0 )) / SUMPRODUCT(IF( ('xUS Opp Value'!$J$4:$J$2041>0) * ( ('xUS Opp Value'!$E$4:$E$2041=$L19) + ('xUS Opp Value'!$E$4:$E$2041="") > 0 ), 'xUS Opp Value'!H$4:H$2041/'xUS Opp Value'!$J$4:$J$2041, 0)),"")} | U19: {=IFERROR(SUMPRODUCT('xUS Opp Value'!I$4:I$2041, --('xUS Opp Value'!$J$4:$J$2041>0), --( ('xUS Opp Value'!$E$4:$E$2041=$L19) + ('xUS Opp Value'!$E$4:$E$2041="") > 0 )) / SUMPRODUCT(IF( ('xUS Opp Value'!$J$4:$J$2041>0) * ( ('xUS Opp Value'!$E$4:$E$2041=$L19) + ('xUS Opp Value'!$E$4:$E$2041="") > 0 ), 'xUS Opp Value'!I$4:I$2041/'xUS Opp Value'!$J$4:$J$2041, 0)),"")}
A20: DE EQ | B20: Germany | C20: =SUMIF('xUS Opp Value'!E:E,'Portfolio Metrics '!B20,'xUS Opp Value'!G:G)/100 -> 0.06 | D20: =SUMIF('xUS Opp Value'!E:E,'Portfolio Metrics '!B20,'xUS Opp Value'!H:H)/100 -> 0.062956637 | E20: =SUMIF('xUS Opp Value'!E:E,'Portfolio Metrics '!B20,'xUS Opp Value'!I:I)/100 -> 0.0508 | F20: =INDEX(Algo!$D:$D,MATCH('Portfolio Metrics '!A20,Algo!A:A,0)) -> 0.0487 | G20: =C20-E20 -> 0.0092 | H20: =C20-F20 -> 0.0113 | I20: =INDEX(#REF!,MATCH('Portfolio Metrics '!A20,#REF!,0)) -> #REF! | J20: =C20-I20 -> #REF! | L20: Germany | M20: {=IFERROR(SUMPRODUCT('xUS Opp Value'!G$4:G$2041, --('xUS Opp Value'!$L$4:$L$2041>0), --( ('xUS Opp Value'!$E$4:$E$2041=$L20) + ('xUS Opp Value'!$E$4:$E$2041="") > 0 )) / SUMPRODUCT(IF( ('xUS Opp Value'!$L$4:$L$2041>0) * ( ('xUS Opp Value'!$E$4:$E$2041=$L20) + ('xUS Opp Value'!$E$4:$E$2041="") > 0 ), 'xUS Opp Value'!G$4:G$2041/'xUS Opp Value'!$L$4:$L$2041, 0)),"")} | N20: {=IFERROR(SUMPRODUCT('xUS Opp Value'!H$4:H$2041, --('xUS Opp Value'!$L$4:$L$2041>0), --( ('xUS Opp Value'!$E$4:$E$2041=$L20) + ('xUS Opp Value'!$E$4:$E$2041="") > 0 )) / SUMPRODUCT(IF( ('xUS Opp Value'!$L$4:$L$2041>0) * ( ('xUS Opp Value'!$E$4:$E$2041=$L20) + ('xUS Opp Value'!$E$4:$E$2041="") > 0 ), 'xUS Opp Value'!H$4:H$2041/'xUS Opp Value'!$L$4:$L$2041, 0)),"")} | O20: {=IFERROR(SUMPRODUCT('xUS Opp Value'!I$4:I$2041, --('xUS Opp Value'!$L$4:$L$2041>0), --( ('xUS Opp Value'!$E$4:$E$2041=$L20) + ('xUS Opp Value'!$E$4:$E$2041="") > 0 )) / SUMPRODUCT(IF( ('xUS Opp Value'!$L$4:$L$2041>0) * ( ('xUS Opp Value'!$E$4:$E$2041=$L20) + ('xUS Opp Value'!$E$4:$E$2041="") > 0 ), 'xUS Opp Value'!I$4:I$2041/'xUS Opp Value'!$L$4:$L$2041, 0)),"")} | P20: =IFERROR((1/S20)-1,"") | Q20: =IFERROR((1/T20)-1,"") | R20: =IFERROR((1/U20)-1,"") | S20: {=IFERROR(SUMPRODUCT('xUS Opp Value'!G$4:G$2041, --('xUS Opp Value'!$J$4:$J$2041>0), --( ('xUS Opp Value'!$E$4:$E$2041=$L20) + ('xUS Opp Value'!$E$4:$E$2041="") > 0 )) / SUMPRODUCT(IF( ('xUS Opp Value'!$J$4:$J$2041>0) * ( ('xUS Opp Value'!$E$4:$E$2041=$L20) + ('xUS Opp Value'!$E$4:$E$2041="") > 0 ), 'xUS Opp Value'!G$4:G$2041/'xUS Opp Value'!$J$4:$J$2041, 0)),"")} | T20: {=IFERROR(SUMPRODUCT('xUS Opp Value'!H$4:H$2041, --('xUS Opp Value'!$J$4:$J$2041>0), --( ('xUS Opp Value'!$E$4:$E$2041=$L20) + ('xUS Opp Value'!$E$4:$E$2041="") > 0 )) / SUMPRODUCT(IF( ('xUS Opp Value'!$J$4:$J$2041>0) * ( ('xUS Opp Value'!$E$4:$E$2041=$L20) + ('xUS Opp Value'!$E$4:$E$2041="") > 0 ), 'xUS Opp Value'!H$4:H$2041/'xUS Opp Value'!$J$4:$J$2041, 0)),"")} | U20: {=IFERROR(SUMPRODUCT('xUS Opp Value'!I$4:I$2041, --('xUS Opp Value'!$J$4:$J$2041>0), --( ('xUS Opp Value'!$E$4:$E$2041=$L20) + ('xUS Opp Value'!$E$4:$E$2041="") > 0 )) / SUMPRODUCT(IF( ('xUS Opp Value'!$J$4:$J$2041>0) * ( ('xUS Opp Value'!$E$4:$E$2041=$L20) + ('xUS Opp Value'!$E$4:$E$2041="") > 0 ), 'xUS Opp Value'!I$4:I$2041/'xUS Opp Value'!$J$4:$J$2041, 0)),"")}
A21: AT EQ | B21: Austria | C21: =SUMIF('xUS Opp Value'!E:E,'Portfolio Metrics '!B21,'xUS Opp Value'!G:G)/100 -> 0 | D21: =SUMIF('xUS Opp Value'!E:E,'Portfolio Metrics '!B21,'xUS Opp Value'!H:H)/100 -> 0 | E21: =SUMIF('xUS Opp Value'!E:E,'Portfolio Metrics '!B21,'xUS Opp Value'!I:I)/100 -> 0.0021 | F21: =INDEX(Algo!$D:$D,MATCH('Portfolio Metrics '!A21,Algo!A:A,0)) -> 0.0104 | G21: =C21-E21 -> -0.0021 | H21: =C21-F21 -> -0.0104 | I21: =INDEX(#REF!,MATCH('Portfolio Metrics '!A21,#REF!,0)) -> #REF! | J21: =C21-I21 -> #REF! | L21: Austria | M21: {=IFERROR(SUMPRODUCT('xUS Opp Value'!G$4:G$2041, --('xUS Opp Value'!$L$4:$L$2041>0), --( ('xUS Opp Value'!$E$4:$E$2041=$L21) + ('xUS Opp Value'!$E$4:$E$2041="") > 0 )) / SUMPRODUCT(IF( ('xUS Opp Value'!$L$4:$L$2041>0) * ( ('xUS Opp Value'!$E$4:$E$2041=$L21) + ('xUS Opp Value'!$E$4:$E$2041="") > 0 ), 'xUS Opp Value'!G$4:G$2041/'xUS Opp Value'!$L$4:$L$2041, 0)),"")} | N21: {=IFERROR(SUMPRODUCT('xUS Opp Value'!H$4:H$2041, --('xUS Opp Value'!$L$4:$L$2041>0), --( ('xUS Opp Value'!$E$4:$E$2041=$L21) + ('xUS Opp Value'!$E$4:$E$2041="") > 0 )) / SUMPRODUCT(IF( ('xUS Opp Value'!$L$4:$L$2041>0) * ( ('xUS Opp Value'!$E$4:$E$2041=$L21) + ('xUS Opp Value'!$E$4:$E$2041="") > 0 ), 'xUS Opp Value'!H$4:H$2041/'xUS Opp Value'!$L$4:$L$2041, 0)),"")} | O21: {=IFERROR(SUMPRODUCT('xUS Opp Value'!I$4:I$2041, --('xUS Opp Value'!$L$4:$L$2041>0), --( ('xUS Opp Value'!$E$4:$E$2041=$L21) + ('xUS Opp Value'!$E$4:$E$2041="") > 0 )) / SUMPRODUCT(IF( ('xUS Opp Value'!$L$4:$L$2041>0) * ( ('xUS Opp Value'!$E$4:$E$2041=$L21) + ('xUS Opp Value'!$E$4:$E$2041="") > 0 ), 'xUS Opp Value'!I$4:I$2041/'xUS Opp Value'!$L$4:$L$2041, 0)),"")} | P21: =IFERROR((1/S21)-1,"") | Q21: =IFERROR((1/T21)-1,"") | R21: =IFERROR((1/U21)-1,"") | S21: {=IFERROR(SUMPRODUCT('xUS Opp Value'!G$4:G$2041, --('xUS Opp Value'!$J$4:$J$2041>0), --( ('xUS Opp Value'!$E$4:$E$2041=$L21) + ('xUS Opp Value'!$E$4:$E$2041="") > 0 )) / SUMPRODUCT(IF( ('xUS Opp Value'!$J$4:$J$2041>0) * ( ('xUS Opp Value'!$E$4:$E$2041=$L21) + ('xUS Opp Value'!$E$4:$E$2041="") > 0 ), 'xUS Opp Value'!G$4:G$2041/'xUS Opp Value'!$J$4:$J$2041, 0)),"")} | T21: {=IFERROR(SUMPRODUCT('xUS Opp Value'!H$4:H$2041, --('xUS Opp Value'!$J$4:$J$2041>0), --( ('xUS Opp Value'!$E$4:$E$2041=$L21) + ('xUS Opp Value'!$E$4:$E$2041="") > 0 )) / SUMPRODUCT(IF( ('xUS Opp Value'!$J$4:$J$2041>0) * ( ('xUS Opp Value'!$E$4:$E$2041=$L21) + ('xUS Opp Value'!$E$4:$E$2041="") > 0 ), 'xUS Opp Value'!H$4:H$2041/'xUS Opp Value'!$J$4:$J$2041, 0)),"")} | U21: {=IFERROR(SUMPRODUCT('xUS Opp Value'!I$4:I$2041, --('xUS Opp Value'!$J$4:$J$2041>0), --( ('xUS Opp Value'!$E$4:$E$2041=$L21) + ('xUS Opp Value'!$E$4:$E$2041="") > 0 )) / SUMPRODUCT(IF( ('xUS Opp Value'!$J$4:$J$2041>0) * ( ('xUS Opp Value'!$E$4:$E$2041=$L21) + ('xUS Opp Value'!$E$4:$E$2041="") > 0 ), 'xUS Opp Value'!I$4:I$2041/'xUS Opp Value'!$J$4:$J$2041, 0)),"")}
A22: BE EQ | B22: Belgium | C22: =SUMIF('xUS Opp Value'!E:E,'Portfolio Metrics '!B22,'xUS Opp Value'!G:G)/100 -> 0 | D22: =SUMIF('xUS Opp Value'!E:E,'Portfolio Metrics '!B22,'xUS Opp Value'!H:H)/100 -> 0 | E22: =SUMIF('xUS Opp Value'!E:E,'Portfolio Metrics '!B22,'xUS Opp Value'!I:I)/100 -> 0.0055 | F22: =INDEX(Algo!$D:$D,MATCH('Portfolio Metrics '!A22,Algo!A:A,0)) -> 0.0156 | G22: =C22-E22 -> -0.0055 | H22: =C22-F22 -> -0.0156 | I22: =INDEX(#REF!,MATCH('Portfolio Metrics '!A22,#REF!,0)) -> #REF! | J22: =C22-I22 -> #REF! | L22: Belgium | M22: {=IFERROR(SUMPRODUCT('xUS Opp Value'!G$4:G$2041, --('xUS Opp Value'!$L$4:$L$2041>0), --( ('xUS Opp Value'!$E$4:$E$2041=$L22) + ('xUS Opp Value'!$E$4:$E$2041="") > 0 )) / SUMPRODUCT(IF( ('xUS Opp Value'!$L$4:$L$2041>0) * ( ('xUS Opp Value'!$E$4:$E$2041=$L22) + ('xUS Opp Value'!$E$4:$E$2041="") > 0 ), 'xUS Opp Value'!G$4:G$2041/'xUS Opp Value'!$L$4:$L$2041, 0)),"")} | N22: {=IFERROR(SUMPRODUCT('xUS Opp Value'!H$4:H$2041, --('xUS Opp Value'!$L$4:$L$2041>0), --( ('xUS Opp Value'!$E$4:$E$2041=$L22) + ('xUS Opp Value'!$E$4:$E$2041="") > 0 )) / SUMPRODUCT(IF( ('xUS Opp Value'!$L$4:$L$2041>0) * ( ('xUS Opp Value'!$E$4:$E$2041=$L22) + ('xUS Opp Value'!$E$4:$E$2041="") > 0 ), 'xUS Opp Value'!H$4:H$2041/'xUS Opp Value'!$L$4:$L$2041, 0)),"")} | O22: {=IFERROR(SUMPRODUCT('xUS Opp Value'!I$4:I$2041, --('xUS Opp Value'!$L$4:$L$2041>0), --( ('xUS Opp Value'!$E$4:$E$2041=$L22) + ('xUS Opp Value'!$E$4:$E$2041="") > 0 )) / SUMPRODUCT(IF( ('xUS Opp Value'!$L$4:$L$2041>0) * ( ('xUS Opp Value'!$E$4:$E$2041=$L22) + ('xUS Opp Value'!$E$4:$E$2041="") > 0 ), 'xUS Opp Value'!I$4:I$2041/'xUS Opp Value'!$L$4:$L$2041, 0)),"")} | P22: =IFERROR((1/S22)-1,"") | Q22: =IFERROR((1/T22)-1,"") | R22: =IFERROR((1/U22)-1,"") | S22: {=IFERROR(SUMPRODUCT('xUS Opp Value'!G$4:G$2041, --('xUS Opp Value'!$J$4:$J$2041>0), --( ('xUS Opp Value'!$E$4:$E$2041=$L22) + ('xUS Opp Value'!$E$4:$E$2041="") > 0 )) / SUMPRODUCT(IF( ('xUS Opp Value'!$J$4:$J$2041>0) * ( ('xUS Opp Value'!$E$4:$E$2041=$L22) + ('xUS Opp Value'!$E$4:$E$2041="") > 0 ), 'xUS Opp Value'!G$4:G$2041/'xUS Opp Value'!$J$4:$J$2041, 0)),"")} | T22: {=IFERROR(SUMPRODUCT('xUS Opp Value'!H$4:H$2041, --('xUS Opp Value'!$J$4:$J$2041>0), --( ('xUS Opp Value'!$E$4:$E$2041=$L22) + ('xUS Opp Value'!$E$4:$E$2041="") > 0 )) / SUMPRODUCT(IF( ('xUS Opp Value'!$J$4:$J$2041>0) * ( ('xUS Opp Value'!$E$4:$E$2041=$L22) + ('xUS Opp Value'!$E$4:$E$2041="") > 0 ), 'xUS Opp Value'!H$4:H$2041/'xUS Opp Value'!$J$4:$J$2041, 0)),"")} | U22: {=IFERROR(SUMPRODUCT('xUS Opp Value'!I$4:I$2041, --('xUS Opp Value'!$J$4:$J$2041>0), --( ('xUS Opp Value'!$E$4:$E$2041=$L22) + ('xUS Opp Value'!$E$4:$E$2041="") > 0 )) / SUMPRODUCT(IF( ('xUS Opp Value'!$J$4:$J$2041>0) * ( ('xUS Opp Value'!$E$4:$E$2041=$L22) + ('xUS Opp Value'!$E$4:$E$2041="") > 0 ), 'xUS Opp Value'!I$4:I$2041/'xUS Opp Value'!$J$4:$J$2041, 0)),"")}
A23: DK EQ | B23: Denmark | C23: =SUMIF('xUS Opp Value'!E:E,'Portfolio Metrics '!B23,'xUS Opp Value'!G:G)/100 -> 0.0225 | D23: =SUMIF('xUS Opp Value'!E:E,'Portfolio Metrics '!B23,'xUS Opp Value'!H:H)/100 -> 0.015934018 | E23: =SUMIF('xUS Opp Value'!E:E,'Portfolio Metrics '!B23,'xUS Opp Value'!I:I)/100 -> 0.0095 | F23: =INDEX(Algo!$D:$D,MATCH('Portfolio Metrics '!A23,Algo!A:A,0)) -> 0.0345 | G23: =C23-E23 -> 0.013 | H23: =C23-F23 -> -0.012 | I23: =INDEX(#REF!,MATCH('Portfolio Metrics '!A23,#REF!,0)) -> #REF! | J23: =C23-I23 -> #REF! | L23: Denmark | M23: {=IFERROR(SUMPRODUCT('xUS Opp Value'!G$4:G$2041, --('xUS Opp Value'!$L$4:$L$2041>0), --( ('xUS Opp Value'!$E$4:$E$2041=$L23) + ('xUS Opp Value'!$E$4:$E$2041="") > 0 )) / SUMPRODUCT(IF( ('xUS Opp Value'!$L$4:$L$2041>0) * ( ('xUS Opp Value'!$E$4:$E$2041=$L23) + ('xUS Opp Value'!$E$4:$E$2041="") > 0 ), 'xUS Opp Value'!G$4:G$2041/'xUS Opp Value'!$L$4:$L$2041, 0)),"")} | N23: {=IFERROR(SUMPRODUCT('xUS Opp Value'!H$4:H$2041, --('xUS Opp Value'!$L$4:$L$2041>0), --( ('xUS Opp Value'!$E$4:$E$2041=$L23) + ('xUS Opp Value'!$E$4:$E$2041="") > 0 )) / SUMPRODUCT(IF( ('xUS Opp Value'!$L$4:$L$2041>0) * ( ('xUS Opp Value'!$E$4:$E$2041=$L23) + ('xUS Opp Value'!$E$4:$E$2041="") > 0 ), 'xUS Opp Value'!H$4:H$2041/'xUS Opp Value'!$L$4:$L$2041, 0)),"")} | O23: {=IFERROR(SUMPRODUCT('xUS Opp Value'!I$4:I$2041, --('xUS Opp Value'!$L$4:$L$2041>0), --( ('xUS Opp Value'!$E$4:$E$2041=$L23) + ('xUS Opp Value'!$E$4:$E$2041="") > 0 )) / SUMPRODUCT(IF( ('xUS Opp Value'!$L$4:$L$2041>0) * ( ('xUS Opp Value'!$E$4:$E$2041=$L23) + ('xUS Opp Value'!$E$4:$E$2041="") > 0 ), 'xUS Opp Value'!I$4:I$2041/'xUS Opp Value'!$L$4:$L$2041, 0)),"")} | P23: =IFERROR((1/S23)-1,"") | Q23: =IFERROR((1/T23)-1,"") | R23: =IFERROR((1/U23)-1,"") | S23: {=IFERROR(SUMPRODUCT('xUS Opp Value'!G$4:G$2041, --('xUS Opp Value'!$J$4:$J$2041>0), --( ('xUS Opp Value'!$E$4:$E$2041=$L23) + ('xUS Opp Value'!$E$4:$E$2041="") > 0 )) / SUMPRODUCT(IF( ('xUS Opp Value'!$J$4:$J$2041>0) * ( ('xUS Opp Value'!$E$4:$E$2041=$L23) + ('xUS Opp Value'!$E$4:$E$2041="") > 0 ), 'xUS Opp Value'!G$4:G$2041/'xUS Opp Value'!$J$4:$J$2041, 0)),"")} | T23: {=IFERROR(SUMPRODUCT('xUS Opp Value'!H$4:H$2041, --('xUS Opp Value'!$J$4:$J$2041>0), --( ('xUS Opp Value'!$E$4:$E$2041=$L23) + ('xUS Opp Value'!$E$4:$E$2041="") > 0 )) / SUMPRODUCT(IF( ('xUS Opp Value'!$J$4:$J$2041>0) * ( ('xUS Opp Value'!$E$4:$E$2041=$L23) + ('xUS Opp Value'!$E$4:$E$2041="") > 0 ), 'xUS Opp Value'!H$4:H$2041/'xUS Opp Value'!$J$4:$J$2041, 0)),"")} | U23: {=IFERROR(SUMPRODUCT('xUS Opp Value'!I$4:I$2041, --('xUS Opp Value'!$J$4:$J$2041>0), --( ('xUS Opp Value'!$E$4:$E$2041=$L23) + ('xUS Opp Value'!$E$4:$E$2041="") > 0 )) / SUMPRODUCT(IF( ('xUS Opp Value'!$J$4:$J$2041>0) * ( ('xUS Opp Value'!$E$4:$E$2041=$L23) + ('xUS Opp Value'!$E$4:$E$2041="") > 0 ), 'xUS Opp Value'!I$4:I$2041/'xUS Opp Value'!$J$4:$J$2041, 0)),"")}
A24: ES EQ | B24: Spain | C24: =SUMIF('xUS Opp Value'!E:E,'Portfolio Metrics '!B24,'xUS Opp Value'!G:G)/100 -> 0.0125 | D24: =SUMIF('xUS Opp Value'!E:E,'Portfolio Metrics '!B24,'xUS Opp Value'!H:H)/100 -> 0.012613893 | E24: =SUMIF('xUS Opp Value'!E:E,'Portfolio Metrics '!B24,'xUS Opp Value'!I:I)/100 -> 0.021 | F24: =INDEX(Algo!$D:$D,MATCH('Portfolio Metrics '!A24,Algo!A:A,0)) -> 0.0145 | G24: =C24-E24 -> -0.0085 | H24: =C24-F24 -> -0.002 | I24: =INDEX(#REF!,MATCH('Portfolio Metrics '!A24,#REF!,0)) -> #REF! | J24: =C24-I24 -> #REF! | L24: Spain | M24: {=IFERROR(SUMPRODUCT('xUS Opp Value'!G$4:G$2041, --('xUS Opp Value'!$L$4:$L$2041>0), --( ('xUS Opp Value'!$E$4:$E$2041=$L24) + ('xUS Opp Value'!$E$4:$E$2041="") > 0 )) / SUMPRODUCT(IF( ('xUS Opp Value'!$L$4:$L$2041>0) * ( ('xUS Opp Value'!$E$4:$E$2041=$L24) + ('xUS Opp Value'!$E$4:$E$2041="") > 0 ), 'xUS Opp Value'!G$4:G$2041/'xUS Opp Value'!$L$4:$L$2041, 0)),"")} | N24: {=IFERROR(SUMPRODUCT('xUS Opp Value'!H$4:H$2041, --('xUS Opp Value'!$L$4:$L$2041>0), --( ('xUS Opp Value'!$E$4:$E$2041=$L24) + ('xUS Opp Value'!$E$4:$E$2041="") > 0 )) / SUMPRODUCT(IF( ('xUS Opp Value'!$L$4:$L$2041>0) * ( ('xUS Opp Value'!$E$4:$E$2041=$L24) + ('xUS Opp Value'!$E$4:$E$2041="") > 0 ), 'xUS Opp Value'!H$4:H$2041/'xUS Opp Value'!$L$4:$L$2041, 0)),"")} | O24: {=IFERROR(SUMPRODUCT('xUS Opp Value'!I$4:I$2041, --('xUS Opp Value'!$L$4:$L$2041>0), --( ('xUS Opp Value'!$E$4:$E$2041=$L24) + ('xUS Opp Value'!$E$4:$E$2041="") > 0 )) / SUMPRODUCT(IF( ('xUS Opp Value'!$L$4:$L$2041>0) * ( ('xUS Opp Value'!$E$4:$E$2041=$L24) + ('xUS Opp Value'!$E$4:$E$2041="") > 0 ), 'xUS Opp Value'!I$4:I$2041/'xUS Opp Value'!$L$4:$L$2041, 0)),"")} | P24: =IFERROR((1/S24)-1,"") | Q24: =IFERROR((1/T24)-1,"") | R24: =IFERROR((1/U24)-1,"") | S24: {=IFERROR(SUMPRODUCT('xUS Opp Value'!G$4:G$2041, --('xUS Opp Value'!$J$4:$J$2041>0), --( ('xUS Opp Value'!$E$4:$E$2041=$L24) + ('xUS Opp Value'!$E$4:$E$2041="") > 0 )) / SUMPRODUCT(IF( ('xUS Opp Value'!$J$4:$J$2041>0) * ( ('xUS Opp Value'!$E$4:$E$2041=$L24) + ('xUS Opp Value'!$E$4:$E$2041="") > 0 ), 'xUS Opp Value'!G$4:G$2041/'xUS Opp Value'!$J$4:$J$2041, 0)),"")} | T24: {=IFERROR(SUMPRODUCT('xUS Opp Value'!H$4:H$2041, --('xUS Opp Value'!$J$4:$J$2041>0), --( ('xUS Opp Value'!$E$4:$E$2041=$L24) + ('xUS Opp Value'!$E$4:$E$2041="") > 0 )) / SUMPRODUCT(IF( ('xUS Opp Value'!$J$4:$J$2041>0) * ( ('xUS Opp Value'!$E$4:$E$2041=$L24) + ('xUS Opp Value'!$E$4:$E$2041="") > 0 ), 'xUS Opp Value'!H$4:H$2041/'xUS Opp Value'!$J$4:$J$2041, 0)),"")} | U24: {=IFERROR(SUMPRODUCT('xUS Opp Value'!I$4:I$2041, --('xUS Opp Value'!$J$4:$J$2041>0), --( ('xUS Opp Value'!$E$4:$E$2041=$L24) + ('xUS Opp Value'!$E$4:$E$2041="") > 0 )) / SUMPRODUCT(IF( ('xUS Opp Value'!$J$4:$J$2041>0) * ( ('xUS Opp Value'!$E$4:$E$2041=$L24) + ('xUS Opp Value'!$E$4:$E$2041="") > 0 ), 'xUS Opp Value'!I$4:I$2041/'xUS Opp Value'!$J$4:$J$2041, 0)),"")}
A25: FI EQ | B25: Finland | C25: =SUMIF('xUS Opp Value'!E:E,'Portfolio Metrics '!B25,'xUS Opp Value'!G:G)/100 -> 0 | D25: =SUMIF('xUS Opp Value'!E:E,'Portfolio Metrics '!B25,'xUS Opp Value'!H:H)/100 -> 0 | E25: =SUMIF('xUS Opp Value'!E:E,'Portfolio Metrics '!B25,'xUS Opp Value'!I:I)/100 -> 0.0059 | F25: =INDEX(Algo!$D:$D,MATCH('Portfolio Metrics '!A25,Algo!A:A,0)) -> 0.0187 | G25: =C25-E25 -> -0.0059 | H25: =C25-F25 -> -0.0187 | I25: =INDEX(#REF!,MATCH('Portfolio Metrics '!A25,#REF!,0)) -> #REF! | J25: =C25-I25 -> #REF! | L25: Finland | M25: {=IFERROR(SUMPRODUCT('xUS Opp Value'!G$4:G$2041, --('xUS Opp Value'!$L$4:$L$2041>0), --( ('xUS Opp Value'!$E$4:$E$2041=$L25) + ('xUS Opp Value'!$E$4:$E$2041="") > 0 )) / SUMPRODUCT(IF( ('xUS Opp Value'!$L$4:$L$2041>0) * ( ('xUS Opp Value'!$E$4:$E$2041=$L25) + ('xUS Opp Value'!$E$4:$E$2041="") > 0 ), 'xUS Opp Value'!G$4:G$2041/'xUS Opp Value'!$L$4:$L$2041, 0)),"")} | N25: {=IFERROR(SUMPRODUCT('xUS Opp Value'!H$4:H$2041, --('xUS Opp Value'!$L$4:$L$2041>0), --( ('xUS Opp Value'!$E$4:$E$2041=$L25) + ('xUS Opp Value'!$E$4:$E$2041="") > 0 )) / SUMPRODUCT(IF( ('xUS Opp Value'!$L$4:$L$2041>0) * ( ('xUS Opp Value'!$E$4:$E$2041=$L25) + ('xUS Opp Value'!$E$4:$E$2041="") > 0 ), 'xUS Opp Value'!H$4:H$2041/'xUS Opp Value'!$L$4:$L$2041, 0)),"")} | O25: {=IFERROR(SUMPRODUCT('xUS Opp Value'!I$4:I$2041, --('xUS Opp Value'!$L$4:$L$2041>0), --( ('xUS Opp Value'!$E$4:$E$2041=$L25) + ('xUS Opp Value'!$E$4:$E$2041="") > 0 )) / SUMPRODUCT(IF( ('xUS Opp Value'!$L$4:$L$2041>0) * ( ('xUS Opp Value'!$E$4:$E$2041=$L25) + ('xUS Opp Value'!$E$4:$E$2041="") > 0 ), 'xUS Opp Value'!I$4:I$2041/'xUS Opp Value'!$L$4:$L$2041, 0)),"")} | P25: =IFERROR((1/S25)-1,"") | Q25: =IFERROR((1/T25)-1,"") | R25: =IFERROR((1/U25)-1,"") | S25: {=IFERROR(SUMPRODUCT('xUS Opp Value'!G$4:G$2041, --('xUS Opp Value'!$J$4:$J$2041>0), --( ('xUS Opp Value'!$E$4:$E$2041=$L25) + ('xUS Opp Value'!$E$4:$E$2041="") > 0 )) / SUMPRODUCT(IF( ('xUS Opp Value'!$J$4:$J$2041>0) * ( ('xUS Opp Value'!$E$4:$E$2041=$L25) + ('xUS Opp Value'!$E$4:$E$2041="") > 0 ), 'xUS Opp Value'!G$4:G$2041/'xUS Opp Value'!$J$4:$J$2041, 0)),"")} | T25: {=IFERROR(SUMPRODUCT('xUS Opp Value'!H$4:H$2041, --('xUS Opp Value'!$J$4:$J$2041>0), --( ('xUS Opp Value'!$E$4:$E$2041=$L25) + ('xUS Opp Value'!$E$4:$E$2041="") > 0 )) / SUMPRODUCT(IF( ('xUS Opp Value'!$J$4:$J$2041>0) * ( ('xUS Opp Value'!$E$4:$E$2041=$L25) + ('xUS Opp Value'!$E$4:$E$2041="") > 0 ), 'xUS Opp Value'!H$4:H$2041/'xUS Opp Value'!$J$4:$J$2041, 0)),"")} | U25: {=IFERROR(SUMPRODUCT('xUS Opp Value'!I$4:I$2041, --('xUS Opp Value'!$J$4:$J$2041>0), --( ('xUS Opp Value'!$E$4:$E$2041=$L25) + ('xUS Opp Value'!$E$4:$E$2041="") > 0 )) / SUMPRODUCT(IF( ('xUS Opp Value'!$J$4:$J$2041>0) * ( ('xUS Opp Value'!$E$4:$E$2041=$L25) + ('xUS Opp Value'!$E$4:$E$2041="") > 0 ), 'xUS Opp Value'!I$4:I$2041/'xUS Opp Value'!$J$4:$J$2041, 0)),"")}
... A40: BR EQ | B40: Brazil | C40: =SUMIF('xUS Opp Value'!E:E,'Portfolio Metrics '!B40,'xUS Opp Value'!G:G)/100 -> 0.04 | D40: =SUMIF('xUS Opp Value'!E:E,'Portfolio Metrics '!B40,'xUS Opp Value'!H:H)/100 -> 0.048627233 | E40: =SUMIF('xUS Opp Value'!E:E,'Portfolio Metrics '!B40,'xUS Opp Value'!I:I)/100 -> 0.0137 | F40: =INDEX(Algo!$D:$D,MATCH('Portfolio Metrics '!A40,Algo!A:A,0)) -> 0.0496 | G40: =C40-E40 -> 0.0263 | H40: =C40-F40 -> -0.0096 | I40: =INDEX(#REF!,MATCH('Portfolio Metrics '!A40,#REF!,0)) -> #REF! | J40: =C40-I40 -> #REF! | L40: Brazil | M40: {=IFERROR(SUMPRODUCT('xUS Opp Value'!G$4:G$2041, --('xUS Opp Value'!$L$4:$L$2041>0), --( ('xUS Opp Value'!$E$4:$E$2041=$L40) + ('xUS Opp Value'!$E$4:$E$2041="") > 0 )) / SUMPRODUCT(IF( ('xUS Opp Value'!$L$4:$L$2041>0) * ( ('xUS Opp Value'!$E$4:$E$2041=$L40) + ('xUS Opp Value'!$E$4:$E$2041="") > 0 ), 'xUS Opp Value'!G$4:G$2041/'xUS Opp Value'!$L$4:$L$2041, 0)),"")} | N40: {=IFERROR(SUMPRODUCT('xUS Opp Value'!H$4:H$2041, --('xUS Opp Value'!$L$4:$L$2041>0), --( ('xUS Opp Value'!$E$4:$E$2041=$L40) + ('xUS Opp Value'!$E$4:$E$2041="") > 0 )) / SUMPRODUCT(IF( ('xUS Opp Value'!$L$4:$L$2041>0) * ( ('xUS Opp Value'!$E$4:$E$2041=$L40) + ('xUS Opp Value'!$E$4:$E$2041="") > 0 ), 'xUS Opp Value'!H$4:H$2041/'xUS Opp Value'!$L$4:$L$2041, 0)),"")} | O40: {=IFERROR(SUMPRODUCT('xUS Opp Value'!I$4:I$2041, --('xUS Opp Value'!$L$4:$L$2041>0), --( ('xUS Opp Value'!$E$4:$E$2041=$L40) + ('xUS Opp Value'!$E$4:$E$2041="") > 0 )) / SUMPRODUCT(IF( ('xUS Opp Value'!$L$4:$L$2041>0) * ( ('xUS Opp Value'!$E$4:$E$2041=$L40) + ('xUS Opp Value'!$E$4:$E$2041="") > 0 ), 'xUS Opp Value'!I$4:I$2041/'xUS Opp Value'!$L$4:$L$2041, 0)),"")} | P40: =IFERROR((1/S40)-1,"") | Q40: =IFERROR((1/T40)-1,"") | R40: =IFERROR((1/U40)-1,"") | S40: {=IFERROR(SUMPRODUCT('xUS Opp Value'!G$4:G$2041, --('xUS Opp Value'!$J$4:$J$2041>0), --( ('xUS Opp Value'!$E$4:$E$2041=$L40) + ('xUS Opp Value'!$E$4:$E$2041="") > 0 )) / SUMPRODUCT(IF( ('xUS Opp Value'!$J$4:$J$2041>0) * ( ('xUS Opp Value'!$E$4:$E$2041=$L40) + ('xUS Opp Value'!$E$4:$E$2041="") > 0 ), 'xUS Opp Value'!G$4:G$2041/'xUS Opp Value'!$J$4:$J$2041, 0)),"")} | T40: {=IFERROR(SUMPRODUCT('xUS Opp Value'!H$4:H$2041, --('xUS Opp Value'!$J$4:$J$2041>0), --( ('xUS Opp Value'!$E$4:$E$2041=$L40) + ('xUS Opp Value'!$E$4:$E$2041="") > 0 )) / SUMPRODUCT(IF( ('xUS Opp Value'!$J$4:$J$2041>0) * ( ('xUS Opp Value'!$E$4:$E$2041=$L40) + ('xUS Opp Value'!$E$4:$E$2041="") > 0 ), 'xUS Opp Value'!H$4:H$2041/'xUS Opp Value'!$J$4:$J$2041, 0)),"")} | U40: {=IFERROR(SUMPRODUCT('xUS Opp Value'!I$4:I$2041, --('xUS Opp Value'!$J$4:$J$2041>0), --( ('xUS Opp Value'!$E$4:$E$2041=$L40) + ('xUS Opp Value'!$E$4:$E$2041="") > 0 )) / SUMPRODUCT(IF( ('xUS Opp Value'!$J$4:$J$2041>0) * ( ('xUS Opp Value'!$E$4:$E$2041=$L40) + ('xUS Opp Value'!$E$4:$E$2041="") > 0 ), 'xUS Opp Value'!I$4:I$2041/'xUS Opp Value'!$J$4:$J$2041, 0)),"")}
A41: MX EQ | B41: Mexico | C41: =SUMIF('xUS Opp Value'!E:E,'Portfolio Metrics '!B41,'xUS Opp Value'!G:G)/100 -> 0.0275 | D41: =SUMIF('xUS Opp Value'!E:E,'Portfolio Metrics '!B41,'xUS Opp Value'!H:H)/100 -> 0.03238625 | E41: =SUMIF('xUS Opp Value'!E:E,'Portfolio Metrics '!B41,'xUS Opp Value'!I:I)/100 -> 0.0065 | F41: =INDEX(Algo!$D:$D,MATCH('Portfolio Metrics '!A41,Algo!A:A,0)) -> 0.0344 | G41: =C41-E41 -> 0.021 | H41: =C41-F41 -> -0.0069 | I41: =INDEX(#REF!,MATCH('Portfolio Metrics '!A41,#REF!,0)) -> #REF! | J41: =C41-I41 -> #REF! | L41: Mexico | M41: {=IFERROR(SUMPRODUCT('xUS Opp Value'!G$4:G$2041, --('xUS Opp Value'!$L$4:$L$2041>0), --( ('xUS Opp Value'!$E$4:$E$2041=$L41) + ('xUS Opp Value'!$E$4:$E$2041="") > 0 )) / SUMPRODUCT(IF( ('xUS Opp Value'!$L$4:$L$2041>0) * ( ('xUS Opp Value'!$E$4:$E$2041=$L41) + ('xUS Opp Value'!$E$4:$E$2041="") > 0 ), 'xUS Opp Value'!G$4:G$2041/'xUS Opp Value'!$L$4:$L$2041, 0)),"")} | N41: {=IFERROR(SUMPRODUCT('xUS Opp Value'!H$4:H$2041, --('xUS Opp Value'!$L$4:$L$2041>0), --( ('xUS Opp Value'!$E$4:$E$2041=$L41) + ('xUS Opp Value'!$E$4:$E$2041="") > 0 )) / SUMPRODUCT(IF( ('xUS Opp Value'!$L$4:$L$2041>0) * ( ('xUS Opp Value'!$E$4:$E$2041=$L41) + ('xUS Opp Value'!$E$4:$E$2041="") > 0 ), 'xUS Opp Value'!H$4:H$2041/'xUS Opp Value'!$L$4:$L$2041, 0)),"")} | O41: {=IFERROR(SUMPRODUCT('xUS Opp Value'!I$4:I$2041, --('xUS Opp Value'!$L$4:$L$2041>0), --( ('xUS Opp Value'!$E$4:$E$2041=$L41) + ('xUS Opp Value'!$E$4:$E$2041="") > 0 )) / SUMPRODUCT(IF( ('xUS Opp Value'!$L$4:$L$2041>0) * ( ('xUS Opp Value'!$E$4:$E$2041=$L41) + ('xUS Opp Value'!$E$4:$E$2041="") > 0 ), 'xUS Opp Value'!I$4:I$2041/'xUS Opp Value'!$L$4:$L$2041, 0)),"")} | P41: =IFERROR((1/S41)-1,"") | Q41: =IFERROR((1/T41)-1,"") | R41: =IFERROR((1/U41)-1,"") | S41: {=IFERROR(SUMPRODUCT('xUS Opp Value'!G$4:G$2041, --('xUS Opp Value'!$J$4:$J$2041>0), --( ('xUS Opp Value'!$E$4:$E$2041=$B41) + ('xUS Opp Value'!$E$4:$E$2041="") > 0 )) / SUMPRODUCT(IF( ('xUS Opp Value'!$J$4:$J$2041>0) * ( ('xUS Opp Value'!$E$4:$E$2041=$B41) + ('xUS Opp Value'!$E$4:$E$2041="") > 0 ), 'xUS Opp Value'!G$4:G$2041/'xUS Opp Value'!$J$4:$J$2041, 0)),"")} | T41: {=IFERROR(SUMPRODUCT('xUS Opp Value'!H$4:H$2041, --('xUS Opp Value'!$J$4:$J$2041>0), --( ('xUS Opp Value'!$E$4:$E$2041=$B41) + ('xUS Opp Value'!$E$4:$E$2041="") > 0 )) / SUMPRODUCT(IF( ('xUS Opp Value'!$J$4:$J$2041>0) * ( ('xUS Opp Value'!$E$4:$E$2041=$B41) + ('xUS Opp Value'!$E$4:$E$2041="") > 0 ), 'xUS Opp Value'!H$4:H$2041/'xUS Opp Value'!$J$4:$J$2041, 0)),"")} | U41: {=IFERROR(SUMPRODUCT('xUS Opp Value'!I$4:I$2041, --('xUS Opp Value'!$J$4:$J$2041>0), --( ('xUS Opp Value'!$E$4:$E$2041=$B41) + ('xUS Opp Value'!$E$4:$E$2041="") > 0 )) / SUMPRODUCT(IF( ('xUS Opp Value'!$J$4:$J$2041>0) * ( ('xUS Opp Value'!$E$4:$E$2041=$B41) + ('xUS Opp Value'!$E$4:$E$2041="") > 0 ), 'xUS Opp Value'!I$4:I$2041/'xUS Opp Value'!$J$4:$J$2041, 0)),"")}
B45: Sector | C45: Gbl xUS Opp Value (tgt) | D45: Gbl xUS Opp Value (d) | E45: BM | F45: vs. BM
B46: Communication Services | C46: =SUMIF('xUS Opp Value'!F:F,B46,'xUS Opp Value'!G:G)/100 -> 0.07 | D46: =SUMIF('xUS Opp Value'!F:F,B46,'xUS Opp Value'!H:H)/100 -> 0.064810476 | E46: =SUMIF('xUS Opp Value'!F:F,B46,'xUS Opp Value'!I:I)/100 -> 0.0488 | F46: =C46-E46 -> 0.0212
B47: Consumer Discretionary | C47: =SUMIF('xUS Opp Value'!F:F,B47,'xUS Opp Value'!G:G)/100 -> 0.1375 | D47: =SUMIF('xUS Opp Value'!F:F,B47,'xUS Opp Value'!H:H)/100 -> 0.12915218 | E47: =SUMIF('xUS Opp Value'!F:F,B47,'xUS Opp Value'!I:I)/100 -> 0.0871 | F47: =C47-E47 -> 0.0504
B48: Consumer Staples | C48: =SUMIF('xUS Opp Value'!F:F,B48,'xUS Opp Value'!G:G)/100 -> 0.1 | D48: =SUMIF('xUS Opp Value'!F:F,B48,'xUS Opp Value'!H:H)/100 -> 0.097948951 | E48: =SUMIF('xUS Opp Value'!F:F,B48,'xUS Opp Value'!I:I)/100 -> 0.0576 | F48: =C48-E48 -> 0.0424
B49: Energy | C49: =SUMIF('xUS Opp Value'!F:F,B49,'xUS Opp Value'!G:G)/100 -> 0.0525 | D49: =SUMIF('xUS Opp Value'!F:F,B49,'xUS Opp Value'!H:H)/100 -> 0.068924145 | E49: =SUMIF('xUS Opp Value'!F:F,B49,'xUS Opp Value'!I:I)/100 -> 0.0571 | F49: =C49-E49 -> -0.0046
B50: Financials | C50: =SUMIF('xUS Opp Value'!F:F,B50,'xUS Opp Value'!G:G)/100 -> 0.21 | D50: =SUMIF('xUS Opp Value'!F:F,B50,'xUS Opp Value'!H:H)/100 -> 0.21708435 | E50: =SUMIF('xUS Opp Value'!F:F,B50,'xUS Opp Value'!I:I)/100 -> 0.2433 | F50: =C50-E50 -> -0.0333
B51: Health Care | C51: =SUMIF('xUS Opp Value'!F:F,B51,'xUS Opp Value'!G:G)/100 -> 0.1 | D51: =SUMIF('xUS Opp Value'!F:F,B51,'xUS Opp Value'!H:H)/100 -> 0.091431959 | E51: =SUMIF('xUS Opp Value'!F:F,B51,'xUS Opp Value'!I:I)/100 -> 0.0678 | F51: =C51-E51 -> 0.0322
B52: Industrials | C52: =SUMIF('xUS Opp Value'!F:F,B52,'xUS Opp Value'!G:G)/100 -> 0.1175 | D52: =SUMIF('xUS Opp Value'!F:F,B52,'xUS Opp Value'!H:H)/100 -> 0.11898793 | E52: =SUMIF('xUS Opp Value'!F:F,B52,'xUS Opp Value'!I:I)/100 -> 0.1449 | F52: =C52-E52 -> -0.0274
B53: Information Technology | C53: =SUMIF('xUS Opp Value'!F:F,B53,'xUS Opp Value'!G:G)/100 -> 0.1225 | D53: =SUMIF('xUS Opp Value'!F:F,B53,'xUS Opp Value'!H:H)/100 -> 0.12919917 | E53: =SUMIF('xUS Opp Value'!F:F,B53,'xUS Opp Value'!I:I)/100 -> 0.153 | F53: =C53-E53 -> -0.0305
B54: Materials | C54: =SUMIF('xUS Opp Value'!F:F,B54,'xUS Opp Value'!G:G)/100 -> 0.0475 | D54: =SUMIF('xUS Opp Value'!F:F,B54,'xUS Opp Value'!H:H)/100 -> 0.047185844 | E54: =SUMIF('xUS Opp Value'!F:F,B54,'xUS Opp Value'!I:I)/100 -> 0.0702 | F54: =C54-E54 -> -0.0227
B55: Real Estate | C55: =SUMIF('xUS Opp Value'!F:F,B55,'xUS Opp Value'!G:G)/100 -> 0 | D55: =SUMIF('xUS Opp Value'!F:F,B55,'xUS Opp Value'!H:H)/100 -> 0 | E55: =SUMIF('xUS Opp Value'!F:F,B55,'xUS Opp Value'!I:I)/100 -> 0.014 | F55: =C55-E55 -> -0.014
B56: Utilities | C56: =SUMIF('xUS Opp Value'!F:F,B56,'xUS Opp Value'!G:G)/100 -> 0.015 | D56: =SUMIF('xUS Opp Value'!F:F,B56,'xUS Opp Value'!H:H)/100 -> 0.017919445 | E56: =SUMIF('xUS Opp Value'!F:F,B56,'xUS Opp Value'!I:I)/100 -> 0.034 | F56: =C56-E56 -> -0.019
A65: Returns | B65: 45972
B67: 1 Month | I67: Top 10 | K67: YTD
V68: Top 10
I96: Bottom 10 | V96: Bottom 10
A133: Flagged Stocks | C133: =A2 -> as of 4/13/2026
...

Sheet xUS Opp Value (Values)
H1: 98.25
A2: as of 2/18/2025
A3: Stock | B3: ISIN | C3: Ticker | D3: SECID | E3: Country | F3: Sector | G3: Opp Value Weight (tgt) | H3: Opp Value Weight (drifted) | I3: Weight In Benchmark | J3: MER P/Fair Value | K3: Upside to MER Value | L3: Forward PE | M3: P/B | N3: ROE | O3: M* MOAT Rating | P3: Base Currency
A4: 360 Security Technology Inc Class A | B4: CNE100002RZ2 | C4: 601360 | D4: 0P0000VC5A | E4: China | F4: Information Technology | G4: 0 | H4: 0 | I4: 0.00261 | J4: 0 | L4: 0 | M4: 3.021364 | N4: -0.035688 | O4: 0 | P4: Yuan Renminbi
A5: 37 Interactive Entertainment Network Technology Group Co Ltd Class A | B5: CNE1000010N2 | C5: 002555 | D5: 0P0000SMSP | E5: China | F5: Communication Services | G5: 0 | H5: 0 | I5: 0.0018 | J5: 0 | L5: 14.08125 | M5: 4.257408 | N5: 0.207766 | O5: 0 | P5: Yuan Renminbi
A6: 3i Group Ord | B6: GB00B1YW4409 | C6: III | D6: E0GBR00IH4 | E6: 0 | F6: Financials | G6: 0 | H6: 0 | I6: 0.12724 | J6: 0 | L6: 0 | M6: 0 | N6: 0 | O6: 0 | P6: Pound Sterling
A7: 99 Speed Mart Retail Holdings Bhd | B7: MYL5326OO003 | C7: 5326 | D7: 0P0001TIMB | E7: Malaysia | F7: Consumer Staples | G7: 0 | H7: 0 | I7: 0.00473 | J7: 0 | L7: 44.712644 | M7: 17.736867 | N7: 0.409302 | O7: 0 | P7: Malaysian Ringgit
A8: A P Moller Maersk AS Class A | B8: DK0010244425 | C8: MAERSK A | D8: 0P0000A5RS | E8: Denmark | F8: Industrials | G8: 0 | H8: 0 | I8: 0.01871 | J8: 0 | L8: 0 | M8: 0.65527 | N8: 0.115066 | O8: None | P8: Danish Krone
A9: A P Moller Maersk AS Class B | B9: DK0010244508 | C9: MAERSK B | D9: 0P0000A5RL | E9: Denmark | F9: Industrials | G9: 0 | H9: 0 | I9: 0.0251 | J9: 1.3190678 | K9: -0.24188885 | L9: 0 | M9: 0.66131 | N9: 0.115066 | O9: None | P9: Danish Krone
A10: A2A SpA | B10: IT0001233417 | C10: A2A | D10: 0P00009DGW | E10: Italy | F10: Utilities | G10: 0 | H10: 0 | I10: 0.01335 | J10: 0 | L10: 0 | M10: 1.391095 | N10: 0.180129 | O10: 0 | P10: Euro
A11: AAC Technologies Holdings Inc | B11: KYG2953R1149 | C11: 02018 | D11: 0P00009S8U | E11: Hong Kong | F11: Information Technology | G11: 0 | H11: 0 | I11: 0.00978 | J11: 0.82666667 | K11: 0.20967742 | L11: 11.712549 | M11: 1.680496 | N11: 0.079273 | O11: None | P11: Hong Kong Dollar
A12: AB Sagax | B12: SE0009161052 | C12: SAGA D | D12: 0P0001965I | E12: Sweden | F12: Real Estate | G12: 0 | H12: 0 | I12: 0.0012 | J12: 0 | L12: 0 | M12: 0.384285 | N12: 0.136815 | O12: 0 | P12: Swedish Krona
A13: AB Sagax Class B | B13: SE0005127818 | C13: SAGA B | D13: 0P0000YG16 | E13: Sweden | F13: Real Estate | G13: 0 | H13: 0 | I13: 0.01354 | J13: 0 | L13: 0 | M13: 2.207525 | N13: 0.136815 | O13: 0 | P13: Swedish Krona
A14: ABB India Ltd | B14: INE117A01022 | C14: 500002 | D14: 0P0000C20B | E14: India | F14: Industrials | G14: 0 | H14: 0 | I14: 0.00913 | J14: 0 | L14: 76.743416 | M14: 16.700053 | N14: 0.290465 | O14: 0 | P14: Indian Rupee
A15: ABB Ltd | B15: CH0012221716 | C15: ABBN | D15: 0P0000A5G8 | E15: Switzerland | F15: Industrials | G15: 0 | H15: 0 | I15: 0.38791 | J15: 1.26 | K15: -0.20634921 | L15: 26.211341 | M15: 9.708645 | N15: 0.317819 | O15: Wide | P15: Swiss Franc
A16: Aboitiz Power Corp | B16: PHY0005M1090 | C16: AP | D16: 0P0000D4WS | E16: Philippines | F16: Utilities | G16: 0 | H16: 0 | I16: 0.00281 | J16: 0 | L16: 10.989975 | M16: 1.50827 | N16: 0.20178 | O16: 0 | P16: Philippine Peso
A17: Absa Group Ltd | B17: ZAE000255915 | C17: ABG | D17: 0P0000DLRU | E17: South Africa | F17: Financials | G17: 0 | H17: 0 | I17: 0.0374 | J17: 0 | L17: 0 | M17: 1.301442 | N17: 0.164536 | O17: 0 | P17: Rand
A18: Abu Dhabi Commercial Bank | B18: AEA000201011 | C18: ADCB | D18: 0P0000JM1M | E18: United Arab Emirates | F18: Financials | G18: 0 | H18: 0 | I18: 0.0371 | J18: 0 | L18: 9.521849 | M18: 1.533295 | N18: 0.163433 | O18: 0 | P18: UAE Dirham
A19: Abu Dhabi Islamic Bank | B19: AEA000801018 | C19: ADIB | D19: 0P0000JM1N | E19: United Arab Emirates | F19: Financials | G19: 0 | H19: 0 | I19: 0.02737 | J19: 0 | L19: 0 | M19: 3.683558 | N19: 0.297174 | O19: 0 | P19: UAE Dirham
A20: Abu Dhabi National Oil Co For Distribution PJSC | B20: AEA006101017 | C20: ADNOCDIST | D20: 0P0001CEM7 | E20: United Arab Emirates | F20: Consumer Discretionary | G20: 0 | H20: 0 | I20: 0.00912 | J20: 0 | L20: 15 | M20: 19.953832 | N20: 0.815751 | O20: 0 | P20: UAE Dirham
A21: ACC Ltd | B21: INE012A01025 | C21: 500410 | D21: 0P0000B89U | E21: India | F21: Materials | G21: 0 | H21: 0 | I21: 0.00411 | J21: 0 | L21: 0 | M21: 1.573172 | N21: 0.139715 | O21: 0 | P21: Indian Rupee
A22: Accton Technology Corp | B22: TW0002345006 | C22: 2345 | D22: 0P0000B70L | E22: Taiwan | F22: Information Technology | G22: 0 | H22: 0 | I22: 0.05153 | J22: 0 | L22: 27.876823 | M22: 13.355329 | N22: 0.405847 | O22: 0 | P22: New Taiwan Dollar
A23: Ackermans & Van Haaren NV | B23: BE0003764785 | C23: ACKB | D23: 0P0000A5LS | E23: Belgium | F23: Industrials | G23: 0 | H23: 0 | I23: 0.01849 | J23: 0 | L23: 13.355445 | M23: 1.533978 | N23: 0.118951 | O23: 0 | P23: Euro
A24: ACM Research (Shanghai) Inc Class A | B24: CNE100004ZD8 | C24: 688082 | D24: 0P0001NTH0 | E24: China | F24: Information Technology | G24: 0 | H24: 0 | I24: 0.00148 | J24: 0 | L24: 40.066778 | M24: 6.576478 | N24: 0.165999 | O24: 0 | P24: Yuan Renminbi
A25: ACS Actividades de Construccion y Servicios SA | B25: ES0167050915 | C25: ACS | D25: 0P0000A5SO | E25: Spain | F25: Industrials | G25: 0 | H25: 0 | I25: 0.07026 | J25: 0 | L25: 24.230769 | M25: 5.369733 | N25: 0.227454 | O25: 0 | P25: Euro
A26: ACWA Power Co | B26: SA15CGS10H12 | C26: 2082 | D26: 0P0001O3H2 | E26: Saudi Arabia | F26: Utilities | G26: 0 | H26: 0 | I26: 0.01991 | J26: 0 | L26: 0 | M26: 5.104882 | N26: 0.098535 | O26: 0 | P26: Saudi Riyal
A27: Adani Energy Solutions Ltd | B27: INE931S01010 | C27: 539254 | D27: 0P00016H1G | E27: India | F27: Utilities | G27: 0 | H27: 0 | I27: 0.00911 | J27: 0 | L27: 0 | M27: 5.006751 | N27: 0.048255 | O27: 0 | P27: Indian Rupee
... A33: Ades Holding Co | B33: SA55SG6H5716 | C33: 2382 | D33: 0P0001RRFG | E33: Saudi Arabia | F33: Energy | G33: 0 | H33: 0 | I33: 0.00634 | J33: 0 | L33: 0 | M33: 3.199463 | N33: 0.133153 | O33: 0 | P33: Saudi Riyal
A34: adidas AG | B34: DE000A1EWWW0 | C34: ADS | D34: 0P00009QNK | E34: Germany | F34: Consumer Discretionary | G34: 0 | H34: 0 | I34: 0.09007 | J34: 0.81162162 | K34: 0.23210123 | L34: 15.535885 | M34: 4.704184 | N34: 0.164287 | O34: Narrow | P34: Euro
A35: Aditya Birla Capital Ltd | B35: INE674K01013 | C35: 540691 | D35: 0P0001BJU8 | E35: India | F35: Financials | G35: 0 | H35: 0 | I35: 0.00842 | J35: 0 | L35: 19.147497 | M35: 2.804469 | N35: 0.118992 | O35: 0 | P35: Indian Rupee
A36: Admiral Group PLC | B36: GB00B02J6398 | C36: ADM | D36: 0P00007NVV | E36: United Kingdom | F36: Financials | G36: 0 | H36: 0 | I36: 0.02474 | J36: 0.77333333 | K36: 0.29310345 | L36: 12.840832 | M36: 5.797291 | N36: 0.572749 | O36: Narrow | P36: Pound Sterling
A37: ADNOC Drilling Company PJSC | B37: AEA007301012 | C37: ADNOCDRILL | D37: 0P0001NGHS | E37: United Arab Emirates | F37: Energy | G37: 0 | H37: 0 | I37: 0.01089 | J37: 0 | L37: 14.763231 | M37: 5.741967 | N37: 0.380216 | O37: 0 | P37: UAE Dirham
A38: Adnoc Logistics & Services PLC | B38: AEE01268A239 | C38: ADNOCLS | D38: 0P0001R4D5 | E38: United Arab Emirates | F38: Energy | G38: 0 | H38: 0 | I38: 0.0061 | J38: 0 | L38: 11.867306 | M38: 2.247084 | N38: 0.161376 | O38: 0 | P38: UAE Dirham
A39: Advanced Info Service PCL | B39: TH0268010Z03 | C39: ADVANC | D39: 0P0000CG0H | E39: Thailand | F39: Communication Services | G39: 0 | H39: 0 | I39: 0.03798 | J39: 0 | L39: 18.514473 | M39: 11.5171 | N39: 0.385323 | O39: 0 | P39: Baht
A40: Advantech Co Ltd | B40: TW0002395001 | C40: 2395 | D40: 0P0000C217 | E40: Taiwan | F40: Information Technology | G40: 0 | H40: 0 | I40: 0.01386 | J40: 0.78378378 | K40: 0.27586207 | L40: 20.27972 | M40: 4.886005 | N40: 0.187404 | O40: Wide | P40: New Taiwan Dollar
A41: Advantest Corp | B41: JP3122400009 | C41: 6857 | D41: 0P0000AETE | E41: Japan | F41: Information Technology | G41: 0 | H41: 0 | I41: 0.32344 | J41: 1.0845833 | K41: -0.077986938 | L41: 49.774256 | M41: 31.022083 | N41: 0.342074 | O41: Wide | P41: Yen
A42: ANZ Group Holdings Ltd | B42: AU000000ANZ3 | C42: ANZ | D42: 0P00006W6R | E42: Australia | F42: Financials | G42: 0.5 | H42: 0.56 | I42: 0.21922 | J42: 1.1145455 | K42: -0.10277325 | L42: 14.669235 | M42: 1.542886 | N42: 0.083725 | O42: Wide | P42: Australian Dollar
A43: AECC Aero-Engine Controls Co Ltd Class A | B43: CNE000000RM5 | C43: 000738 | D43: 0P00007XNI | E43: China | F43: Industrials | G43: 0 | H43: 0 | I43: 0.00099 | J43: 0 | L43: 0 | M43: 2.713732 | N43: 0.062301 | O43: 0 | P43: Yuan Renminbi
A44: AECC Aviation Power Co Ltd Class A | B44: CNE000000JW1 | C44: 600893 | D44: 0P00007XKQ | E44: China | F44: Industrials | G44: 0 | H44: 0 | I44: 0.00379 | J44: 0 | L44: 0 | M44: 3.251029 | N44: 0.024774 | O44: 0 | P44: Yuan Renminbi
A45: Aena SME SA | B45: ES0105046017 | C45: AENA | D45: 0P00015CW1 | E45: Spain | F45: Industrials | G45: 0 | H45: 0 | I45: 0.0652 | J45: 0 | L45: 15.905063 | M45: 4.591428 | N45: 0.254033 | O45: Narrow | P45: Euro
...

Sheet xUS Opp Value
H1: =SUM(G:G) -> 99
A2: as of 4/13/2026
A3: Stock | B3: ISIN | C3: Ticker | D3: SECID | E3: Country | F3: Sector | G3: Opp Value Weight (tgt) | H3: Opp Value Weight (drifted) | I3: Weight In Benchmark | J3: MER P/Fair Value | K3: Upside to MER Value | L3: Forward PE | M3: P/B | N3: ROE | O3: M* MOAT Rating | P3: Base Currency | Q3: Fair Value Uncertainty
A4: Hitachi Ltd | B4: =INDEX('xUS TME'!B:B,MATCH('xUS Opp Value'!A4,'xUS TME'!A:A,0)) -> JP3788600009 | C4: =INDEX('xUS TME'!C:C,MATCH($B4,'xUS TME'!$B:$B,0)) -> 6501 | D4: =INDEX('xUS TME'!D:D,MATCH(B4,'xUS TME'!$B:$B,0)) -> 0P0000AEUO | E4: =INDEX('xUS TME'!F:F,MATCH(B4,'xUS TME'!$B:$B,0)) -> Japan | F4: =INDEX('xUS TME'!G:G,MATCH(B4,'xUS TME'!$B:$B,0)) -> Industrials | G4: =IFERROR(INDEX(CRIMs!G:G,MATCH(C4,CRIMs!D:D,0)),0) -> 0 | H4: =IFERROR(INDEX(CRIMs!I:I,MATCH(C4,CRIMs!D:D,0)),0) -> 0 | I4: =INDEX('xUS TME'!E:E,MATCH($B4,'xUS TME'!$B:$B,0)) -> 0.39 | J4: =INDEX('xUS TME'!H:H,MATCH(B4,'xUS TME'!$B:$B,0)) -> 0 | K4: =IFERROR((1/J4)-1,"") | L4: =INDEX('xUS TME'!J:J,MATCH('xUS Opp Value'!B4,'xUS TME'!$B:$B,0)) -> 23.03 | M4: =INDEX('xUS TME'!L:L,MATCH('xUS Opp Value'!$B4,'xUS TME'!$B:$B,0)) -> 3.41 | N4: =INDEX('xUS TME'!K:K,MATCH('xUS Opp Value'!$B4,'xUS TME'!$B:$B,0)) -> 0.12 | O4: =INDEX('xUS TME'!I:I,MATCH('xUS Opp Value'!$B4,'xUS TME'!$B:$B,0)) -> None | P4: =INDEX('xUS TME'!M:M,MATCH('xUS Opp Value'!$B4,'xUS TME'!$B:$B,0)) -> Yen | Q4: =INDEX('xUS TME'!N:N,MATCH('xUS Opp Value'!$B4,'xUS TME'!$B:$B,0)) -> Medium
A5: HDFC Bank Ltd | B5: =INDEX('xUS TME'!B:B,MATCH('xUS Opp Value'!A5,'xUS TME'!A:A,0)) -> INE040A01034 | C5: =INDEX('xUS TME'!C:C,MATCH($B5,'xUS TME'!$B:$B,0)) -> HDFCBANK | D5: =INDEX('xUS TME'!D:D,MATCH(B5,'xUS TME'!$B:$B,0)) -> 0P0000C3NZ | E5: =INDEX('xUS TME'!F:F,MATCH(B5,'xUS TME'!$B:$B,0)) -> India | F5: =INDEX('xUS TME'!G:G,MATCH(B5,'xUS TME'!$B:$B,0)) -> Financials | G5: =IFERROR(INDEX(CRIMs!G:G,MATCH(C5,CRIMs!D:D,0)),0) -> 0.75 | H5: =IFERROR(INDEX(CRIMs!I:I,MATCH(C5,CRIMs!D:D,0)),0) -> 0.79836769 | I5: =INDEX('xUS TME'!E:E,MATCH($B5,'xUS TME'!$B:$B,0)) -> 0.27 | J5: =INDEX('xUS TME'!H:H,MATCH(B5,'xUS TME'!$B:$B,0)) -> 0 | K5: =IFERROR((1/J5)-1,"") | L5: =INDEX('xUS TME'!J:J,MATCH('xUS Opp Value'!B5,'xUS TME'!$B:$B,0)) -> 16.38 | M5: =INDEX('xUS TME'!L:L,MATCH('xUS Opp Value'!$B5,'xUS TME'!$B:$B,0)) -> 1.62 | N5: =INDEX('xUS TME'!K:K,MATCH('xUS Opp Value'!$B5,'xUS TME'!$B:$B,0)) -> 0.09 | O5: =INDEX('xUS TME'!I:I,MATCH('xUS Opp Value'!$B5,'xUS TME'!$B:$B,0)) -> Narrow | P5: =INDEX('xUS TME'!M:M,MATCH('xUS Opp Value'!$B5,'xUS TME'!$B:$B,0)) -> Indian Rupee | Q5: =INDEX('xUS TME'!N:N,MATCH('xUS Opp Value'!$B5,'xUS TME'!$B:$B,0)) -> High
A6: Reliance Industries Ltd | B6: =INDEX('xUS TME'!B:B,MATCH('xUS Opp Value'!A6,'xUS TME'!A:A,0)) -> INE002A01018 | C6: =INDEX('xUS TME'!C:C,MATCH($B6,'xUS TME'!$B:$B,0)) -> RELIANCE | D6: =INDEX('xUS TME'!D:D,MATCH(B6,'xUS TME'!$B:$B,0)) -> 0P0000B1W1 | E6: =INDEX('xUS TME'!F:F,MATCH(B6,'xUS TME'!$B:$B,0)) -> India | F6: =INDEX('xUS TME'!G:G,MATCH(B6,'xUS TME'!$B:$B,0)) -> Energy | G6: =IFERROR(INDEX(CRIMs!G:G,MATCH(C6,CRIMs!D:D,0)),0) -> 0 | H6: =IFERROR(INDEX(CRIMs!I:I,MATCH(C6,CRIMs!D:D,0)),0) -> 0 | I6: =INDEX('xUS TME'!E:E,MATCH($B6,'xUS TME'!$B:$B,0)) -> 0.31 | J6: =INDEX('xUS TME'!H:H,MATCH(B6,'xUS TME'!$B:$B,0)) -> 0 | K6: =IFERROR((1/J6)-1,"") | L6: =INDEX('xUS TME'!J:J,MATCH('xUS Opp Value'!B6,'xUS TME'!$B:$B,0)) -> 18.52 | M6: =INDEX('xUS TME'!L:L,MATCH('xUS Opp Value'!$B6,'xUS TME'!$B:$B,0)) -> 2.08 | N6: =INDEX('xUS TME'!K:K,MATCH('xUS Opp Value'!$B6,'xUS TME'!$B:$B,0)) -> 0.1 | O6: =INDEX('xUS TME'!I:I,MATCH('xUS Opp Value'!$B6,'xUS TME'!$B:$B,0)) -> None | P6: =INDEX('xUS TME'!M:M,MATCH('xUS Opp Value'!$B6,'xUS TME'!$B:$B,0)) -> Indian Rupee | Q6: =INDEX('xUS TME'!N:N,MATCH('xUS Opp Value'!$B6,'xUS TME'!$B:$B,0)) -> High
